[2025-04-03T12:48:31.551+0000] {local_task_job_runner.py:123} INFO - ::group::Pre task execution logs
[2025-04-03T12:48:31.560+0000] {taskinstance.py:2614} INFO - Dependencies all met for dep_context=non-requeueable deps ti=<TaskInstance: stock_price_prediction.setup_database manual__2025-04-03T12:48:29.350210+00:00 [queued]>
[2025-04-03T12:48:31.567+0000] {taskinstance.py:2614} INFO - Dependencies all met for dep_context=requeueable deps ti=<TaskInstance: stock_price_prediction.setup_database manual__2025-04-03T12:48:29.350210+00:00 [queued]>
[2025-04-03T12:48:31.567+0000] {taskinstance.py:2867} INFO - Starting attempt 1 of 1
[2025-04-03T12:48:31.576+0000] {taskinstance.py:2890} INFO - Executing <Task(_PythonDecoratedOperator): setup_database> on 2025-04-03 12:48:29.350210+00:00
[2025-04-03T12:48:31.584+0000] {warnings.py:112} WARNING - /home/***/.local/lib/python3.12/site-packages/***/task/task_runner/standard_task_runner.py:70: DeprecationWarning: This process (pid=135) is multi-threaded, use of fork() may lead to deadlocks in the child.
  pid = os.fork()

[2025-04-03T12:48:31.586+0000] {standard_task_runner.py:72} INFO - Started process 136 to run task
[2025-04-03T12:48:31.587+0000] {standard_task_runner.py:104} INFO - Running: ['***', 'tasks', 'run', 'stock_price_prediction', 'setup_database', 'manual__2025-04-03T12:48:29.350210+00:00', '--job-id', '40', '--raw', '--subdir', 'DAGS_FOLDER/project_DAG.py', '--cfg-path', '/tmp/tmpdcsjgcu3']
[2025-04-03T12:48:31.588+0000] {standard_task_runner.py:105} INFO - Job 40: Subtask setup_database
[2025-04-03T12:48:31.624+0000] {task_command.py:467} INFO - Running <TaskInstance: stock_price_prediction.setup_database manual__2025-04-03T12:48:29.350210+00:00 [running]> on host d3a367ad0c84
[2025-04-03T12:48:31.668+0000] {taskinstance.py:3134} INFO - Exporting env vars: AIRFLOW_CTX_DAG_OWNER='***' AIRFLOW_CTX_DAG_ID='stock_price_prediction' AIRFLOW_CTX_TASK_ID='setup_database' AIRFLOW_CTX_EXECUTION_DATE='2025-04-03T12:48:29.350210+00:00' AIRFLOW_CTX_TRY_NUMBER='1' AIRFLOW_CTX_DAG_RUN_ID='manual__2025-04-03T12:48:29.350210+00:00'
[2025-04-03T12:48:31.669+0000] {logging_mixin.py:190} INFO - Task instance is in running state
[2025-04-03T12:48:31.669+0000] {logging_mixin.py:190} INFO -  Previous state of the Task instance: queued
[2025-04-03T12:48:31.669+0000] {logging_mixin.py:190} INFO - Current task name:setup_database state:running start_date:2025-04-03 12:48:31.561320+00:00
[2025-04-03T12:48:31.669+0000] {logging_mixin.py:190} INFO - Dag name:stock_price_prediction and current dag run status:running
[2025-04-03T12:48:31.669+0000] {taskinstance.py:732} INFO - ::endgroup::
[2025-04-03T12:48:31.675+0000] {base.py:84} INFO - Retrieving connection 'is3107_db'
[2025-04-03T12:48:31.677+0000] {taskinstance.py:3313} ERROR - Task failed with exception
Traceback (most recent call last):
  File "/home/airflow/.local/lib/python3.12/site-packages/airflow/models/taskinstance.py", line 768, in _execute_task
    result = _execute_callable(context=context, **execute_callable_kwargs)
             ^^^^^^^^^^^^^^^^^^^^^^^^^^^^^^^^^^^^^^^^^^^^^^^^^^^^^^^^^^^^^
  File "/home/airflow/.local/lib/python3.12/site-packages/airflow/models/taskinstance.py", line 734, in _execute_callable
    return ExecutionCallableRunner(
           ^^^^^^^^^^^^^^^^^^^^^^^^
  File "/home/airflow/.local/lib/python3.12/site-packages/airflow/utils/operator_helpers.py", line 252, in run
    return self.func(*args, **kwargs)
           ^^^^^^^^^^^^^^^^^^^^^^^^^^
  File "/home/airflow/.local/lib/python3.12/site-packages/airflow/models/baseoperator.py", line 424, in wrapper
    return func(self, *args, **kwargs)
           ^^^^^^^^^^^^^^^^^^^^^^^^^^^
  File "/home/airflow/.local/lib/python3.12/site-packages/airflow/decorators/base.py", line 266, in execute
    return_value = super().execute(context)
                   ^^^^^^^^^^^^^^^^^^^^^^^^
  File "/home/airflow/.local/lib/python3.12/site-packages/airflow/models/baseoperator.py", line 424, in wrapper
    return func(self, *args, **kwargs)
           ^^^^^^^^^^^^^^^^^^^^^^^^^^^
  File "/home/airflow/.local/lib/python3.12/site-packages/airflow/operators/python.py", line 238, in execute
    return_value = self.execute_callable()
                   ^^^^^^^^^^^^^^^^^^^^^^^
  File "/home/airflow/.local/lib/python3.12/site-packages/airflow/operators/python.py", line 256, in execute_callable
    return runner.run(*self.op_args, **self.op_kwargs)
           ^^^^^^^^^^^^^^^^^^^^^^^^^^^^^^^^^^^^^^^^^^^
  File "/home/airflow/.local/lib/python3.12/site-packages/airflow/utils/operator_helpers.py", line 252, in run
    return self.func(*args, **kwargs)
           ^^^^^^^^^^^^^^^^^^^^^^^^^^
  File "/opt/airflow/dags/project_DAG.py", line 27, in setup_database
    conn.connect(conn_id=CONN_ID)
  File "/opt/airflow/dags/Connection.py", line 11, in connect
    self.conn = hook.get_conn()
                ^^^^^^^^^^^^^^^
  File "/home/airflow/.local/lib/python3.12/site-packages/airflow/providers/postgres/hooks/postgres.py", line 165, in get_conn
    self.conn = psycopg2.connect(**conn_args)
                ^^^^^^^^^^^^^^^^^^^^^^^^^^^^^
  File "/home/airflow/.local/lib/python3.12/site-packages/psycopg2/__init__.py", line 122, in connect
    conn = _connect(dsn, connection_factory=connection_factory, **kwasync)
           ^^^^^^^^^^^^^^^^^^^^^^^^^^^^^^^^^^^^^^^^^^^^^^^^^^^^^^^^^^^^^^^
psycopg2.OperationalError: connection to server at "***" (172.19.0.2), port 5432 failed: FATAL:  password authentication failed for user "***"

[2025-04-03T12:48:31.683+0000] {logging_mixin.py:190} INFO - Task instance in failure state
[2025-04-03T12:48:31.683+0000] {logging_mixin.py:190} INFO - Task start:2025-04-03 12:48:31.561320+00:00 end:2025-04-03 12:48:31.683473+00:00 duration:0.122153
[2025-04-03T12:48:31.684+0000] {logging_mixin.py:190} INFO - Task:<Task(_PythonDecoratedOperator): setup_database> dag:<DAG: stock_price_prediction> dagrun:<DagRun stock_price_prediction @ 2025-04-03 12:48:29.350210+00:00: manual__2025-04-03T12:48:29.350210+00:00, state:running, queued_at: 2025-04-03 12:48:29.358835+00:00. externally triggered: True>
[2025-04-03T12:48:31.684+0000] {logging_mixin.py:190} INFO - Failure caused by connection to server at "***" (172.19.0.2), port 5432 failed: FATAL:  password authentication failed for user "***"
[2025-04-03T12:48:31.684+0000] {taskinstance.py:1226} INFO - Marking task as FAILED. dag_id=stock_price_prediction, task_id=setup_database, run_id=manual__2025-04-03T12:48:29.350210+00:00, execution_date=20250403T124829, start_date=20250403T124831, end_date=20250403T124831
[2025-04-03T12:48:31.697+0000] {taskinstance.py:341} INFO - ::group::Post task execution logs
[2025-04-03T12:48:31.698+0000] {standard_task_runner.py:124} ERROR - Failed to execute job 40 for task setup_database (connection to server at "***" (172.19.0.2), port 5432 failed: FATAL:  password authentication failed for user "***"
; 136)
Traceback (most recent call last):
  File "/home/airflow/.local/lib/python3.12/site-packages/airflow/task/task_runner/standard_task_runner.py", line 117, in _start_by_fork
    ret = args.func(args, dag=self.dag)
          ^^^^^^^^^^^^^^^^^^^^^^^^^^^^^
  File "/home/airflow/.local/lib/python3.12/site-packages/airflow/cli/cli_config.py", line 49, in command
    return func(*args, **kwargs)
           ^^^^^^^^^^^^^^^^^^^^^
  File "/home/airflow/.local/lib/python3.12/site-packages/airflow/utils/cli.py", line 116, in wrapper
    return f(*args, **kwargs)
           ^^^^^^^^^^^^^^^^^^
  File "/home/airflow/.local/lib/python3.12/site-packages/airflow/cli/commands/task_command.py", line 483, in task_run
    task_return_code = _run_task_by_selected_method(args, _dag, ti)
                       ^^^^^^^^^^^^^^^^^^^^^^^^^^^^^^^^^^^^^^^^^^^^
  File "/home/airflow/.local/lib/python3.12/site-packages/airflow/cli/commands/task_command.py", line 256, in _run_task_by_selected_method
    return _run_raw_task(args, ti)
           ^^^^^^^^^^^^^^^^^^^^^^^
  File "/home/airflow/.local/lib/python3.12/site-packages/airflow/cli/commands/task_command.py", line 341, in _run_raw_task
    return ti._run_raw_task(
           ^^^^^^^^^^^^^^^^^
  File "/home/airflow/.local/lib/python3.12/site-packages/airflow/utils/session.py", line 97, in wrapper
    return func(*args, session=session, **kwargs)
           ^^^^^^^^^^^^^^^^^^^^^^^^^^^^^^^^^^^^^^
  File "/home/airflow/.local/lib/python3.12/site-packages/airflow/models/taskinstance.py", line 3006, in _run_raw_task
    return _run_raw_task(
           ^^^^^^^^^^^^^^
  File "/home/airflow/.local/lib/python3.12/site-packages/airflow/models/taskinstance.py", line 274, in _run_raw_task
    TaskInstance._execute_task_with_callbacks(
  File "/home/airflow/.local/lib/python3.12/site-packages/airflow/models/taskinstance.py", line 3161, in _execute_task_with_callbacks
    result = self._execute_task(context, task_orig)
             ^^^^^^^^^^^^^^^^^^^^^^^^^^^^^^^^^^^^^^
  File "/home/airflow/.local/lib/python3.12/site-packages/airflow/models/taskinstance.py", line 3185, in _execute_task
    return _execute_task(self, context, task_orig)
           ^^^^^^^^^^^^^^^^^^^^^^^^^^^^^^^^^^^^^^^
  File "/home/airflow/.local/lib/python3.12/site-packages/airflow/models/taskinstance.py", line 768, in _execute_task
    result = _execute_callable(context=context, **execute_callable_kwargs)
             ^^^^^^^^^^^^^^^^^^^^^^^^^^^^^^^^^^^^^^^^^^^^^^^^^^^^^^^^^^^^^
  File "/home/airflow/.local/lib/python3.12/site-packages/airflow/models/taskinstance.py", line 734, in _execute_callable
    return ExecutionCallableRunner(
           ^^^^^^^^^^^^^^^^^^^^^^^^
  File "/home/airflow/.local/lib/python3.12/site-packages/airflow/utils/operator_helpers.py", line 252, in run
    return self.func(*args, **kwargs)
           ^^^^^^^^^^^^^^^^^^^^^^^^^^
  File "/home/airflow/.local/lib/python3.12/site-packages/airflow/models/baseoperator.py", line 424, in wrapper
    return func(self, *args, **kwargs)
           ^^^^^^^^^^^^^^^^^^^^^^^^^^^
  File "/home/airflow/.local/lib/python3.12/site-packages/airflow/decorators/base.py", line 266, in execute
    return_value = super().execute(context)
                   ^^^^^^^^^^^^^^^^^^^^^^^^
  File "/home/airflow/.local/lib/python3.12/site-packages/airflow/models/baseoperator.py", line 424, in wrapper
    return func(self, *args, **kwargs)
           ^^^^^^^^^^^^^^^^^^^^^^^^^^^
  File "/home/airflow/.local/lib/python3.12/site-packages/airflow/operators/python.py", line 238, in execute
    return_value = self.execute_callable()
                   ^^^^^^^^^^^^^^^^^^^^^^^
  File "/home/airflow/.local/lib/python3.12/site-packages/airflow/operators/python.py", line 256, in execute_callable
    return runner.run(*self.op_args, **self.op_kwargs)
           ^^^^^^^^^^^^^^^^^^^^^^^^^^^^^^^^^^^^^^^^^^^
  File "/home/airflow/.local/lib/python3.12/site-packages/airflow/utils/operator_helpers.py", line 252, in run
    return self.func(*args, **kwargs)
           ^^^^^^^^^^^^^^^^^^^^^^^^^^
  File "/opt/airflow/dags/project_DAG.py", line 27, in setup_database
    conn.connect(conn_id=CONN_ID)
  File "/opt/airflow/dags/Connection.py", line 11, in connect
    self.conn = hook.get_conn()
                ^^^^^^^^^^^^^^^
  File "/home/airflow/.local/lib/python3.12/site-packages/airflow/providers/postgres/hooks/postgres.py", line 165, in get_conn
    self.conn = psycopg2.connect(**conn_args)
                ^^^^^^^^^^^^^^^^^^^^^^^^^^^^^
  File "/home/airflow/.local/lib/python3.12/site-packages/psycopg2/__init__.py", line 122, in connect
    conn = _connect(dsn, connection_factory=connection_factory, **kwasync)
           ^^^^^^^^^^^^^^^^^^^^^^^^^^^^^^^^^^^^^^^^^^^^^^^^^^^^^^^^^^^^^^^
psycopg2.OperationalError: connection to server at "***" (172.19.0.2), port 5432 failed: FATAL:  password authentication failed for user "***"

[2025-04-03T12:48:31.729+0000] {local_task_job_runner.py:266} INFO - Task exited with return code 1
[2025-04-03T12:48:31.740+0000] {taskinstance.py:3901} INFO - 0 downstream tasks scheduled from follow-on schedule check
[2025-04-03T12:48:31.741+0000] {local_task_job_runner.py:245} INFO - ::endgroup::
